<?xml version="1.0" encoding="UTF-8"?>
<!-- Generated by org.testng.reporters.JUnitReportReporter -->
<testsuite hostname="Ranjeet-MacBook-Pro.local" failures="1" tests="6" name="Com.Ecommerce.TestCases.TC_LoginDataTest" time="92.008" errors="0" timestamp="2023-07-21T23:43:24 IST" skipped="1">
  <testcase classname="Com.Ecommerce.TestCases.TC_LoginDataTest" name="LoginData" time="15.395">
    <failure message="expected [true] but found [false]" type="java.lang.AssertionError">
      <![CDATA[java.lang.AssertionError: expected [true] but found [false]
at org.testng.Assert.fail(Assert.java:110)
at org.testng.Assert.failNotEquals(Assert.java:1577)
at org.testng.Assert.assertTrue(Assert.java:56)
at org.testng.Assert.assertTrue(Assert.java:66)
at Com.Ecommerce.TestCases.TC_LoginDataTest.LoginData(TC_LoginDataTest.java:43)
at java.base/jdk.internal.reflect.DirectMethodHandleAccessor.invoke(DirectMethodHandleAccessor.java:104)
at java.base/java.lang.reflect.Method.invoke(Method.java:577)
at org.testng.internal.invokers.MethodInvocationHelper.invokeMethod(MethodInvocationHelper.java:139)
at org.testng.internal.invokers.TestInvoker.invokeMethod(TestInvoker.java:677)
at org.testng.internal.invokers.TestInvoker.retryFailed(TestInvoker.java:263)
at org.testng.internal.invokers.MethodRunner.runInSequence(MethodRunner.java:62)
at org.testng.internal.invokers.TestInvoker$MethodInvocationAgent.invoke(TestInvoker.java:969)
at org.testng.internal.invokers.TestInvoker.invokeTestMethods(TestInvoker.java:194)
at org.testng.internal.invokers.TestMethodWorker.invokeTestMethods(TestMethodWorker.java:148)
at org.testng.internal.invokers.TestMethodWorker.run(TestMethodWorker.java:128)
at java.base/java.util.ArrayList.forEach(ArrayList.java:1511)
at org.testng.TestRunner.privateRun(TestRunner.java:829)
at org.testng.TestRunner.run(TestRunner.java:602)
at org.testng.SuiteRunner.runTest(SuiteRunner.java:437)
at org.testng.SuiteRunner.runSequentially(SuiteRunner.java:431)
at org.testng.SuiteRunner.privateRun(SuiteRunner.java:391)
at org.testng.SuiteRunner.run(SuiteRunner.java:330)
at org.testng.SuiteRunnerWorker.runSuite(SuiteRunnerWorker.java:52)
at org.testng.SuiteRunnerWorker.run(SuiteRunnerWorker.java:95)
at org.testng.TestNG.runSuitesSequentially(TestNG.java:1256)
at org.testng.TestNG.runSuitesLocally(TestNG.java:1176)
at org.testng.TestNG.runSuites(TestNG.java:1099)
at org.testng.TestNG.run(TestNG.java:1067)
at org.testng.remote.AbstractRemoteTestNG.run(AbstractRemoteTestNG.java:115)
at org.testng.remote.RemoteTestNG.initAndRun(RemoteTestNG.java:251)
at org.testng.remote.RemoteTestNG.main(RemoteTestNG.java:77)
]]>
    </failure>
  </testcase> <!-- LoginData -->
  <system-out/>
  <testcase classname="Com.Ecommerce.TestCases.TC_LoginDataTest" name="LoginData" time="15.749"/>
  <system-out/>
  <testcase classname="Com.Ecommerce.TestCases.TC_LoginDataTest" name="LoginData" time="15.242"/>
  <system-out/>
  <testcase classname="Com.Ecommerce.TestCases.TC_LoginDataTest" name="LoginData" time="15.677">
    <skipped/>
  </testcase> <!-- LoginData -->
  <system-out/>
  <testcase classname="Com.Ecommerce.TestCases.TC_LoginDataTest" name="LoginData" time="14.512"/>
  <system-out/>
  <testcase classname="Com.Ecommerce.TestCases.TC_LoginDataTest" name="LoginData" time="15.433"/>
  <system-out/>
</testsuite> <!-- Com.Ecommerce.TestCases.TC_LoginDataTest -->
